[2022-08-07 18:39:21,070] {taskinstance.py:1179} INFO - Dependencies all met for <TaskInstance: training_pipeline_dag.run_models manual__2022-08-07T18:39:15.608420+00:00 [queued]>
[2022-08-07 18:39:21,081] {taskinstance.py:1179} INFO - Dependencies all met for <TaskInstance: training_pipeline_dag.run_models manual__2022-08-07T18:39:15.608420+00:00 [queued]>
[2022-08-07 18:39:21,082] {taskinstance.py:1376} INFO - 
--------------------------------------------------------------------------------
[2022-08-07 18:39:21,082] {taskinstance.py:1377} INFO - Starting attempt 1 of 1
[2022-08-07 18:39:21,082] {taskinstance.py:1378} INFO - 
--------------------------------------------------------------------------------
[2022-08-07 18:39:21,095] {taskinstance.py:1397} INFO - Executing <Task(PythonOperator): run_models> on 2022-08-07 18:39:15.608420+00:00
[2022-08-07 18:39:21,102] {standard_task_runner.py:52} INFO - Started process 160 to run task
[2022-08-07 18:39:21,105] {standard_task_runner.py:79} INFO - Running: ['***', 'tasks', 'run', 'training_pipeline_dag', 'run_models', 'manual__2022-08-07T18:39:15.608420+00:00', '--job-id', '5', '--raw', '--subdir', 'DAGS_FOLDER/pipeline.py', '--cfg-path', '/tmp/tmpdio54g2e', '--error-file', '/tmp/tmpm11w11w2']
[2022-08-07 18:39:21,107] {standard_task_runner.py:80} INFO - Job 5: Subtask run_models
[2022-08-07 18:39:21,165] {task_command.py:371} INFO - Running <TaskInstance: training_pipeline_dag.run_models manual__2022-08-07T18:39:15.608420+00:00 [running]> on host 6247883ada19
[2022-08-07 18:39:21,243] {taskinstance.py:1591} INFO - Exporting the following env vars:
AIRFLOW_CTX_DAG_OWNER=Gibran Otazo
AIRFLOW_CTX_DAG_ID=training_pipeline_dag
AIRFLOW_CTX_TASK_ID=run_models
AIRFLOW_CTX_EXECUTION_DATE=2022-08-07T18:39:15.608420+00:00
AIRFLOW_CTX_TRY_NUMBER=1
AIRFLOW_CTX_DAG_RUN_ID=manual__2022-08-07T18:39:15.608420+00:00
[2022-08-07 18:39:21,245] {taskinstance.py:1909} ERROR - Task failed with exception
Traceback (most recent call last):
  File "/home/airflow/.local/lib/python3.7/site-packages/airflow/operators/python.py", line 171, in execute
    return_value = self.execute_callable()
  File "/home/airflow/.local/lib/python3.7/site-packages/airflow/operators/python.py", line 189, in execute_callable
    return self.python_callable(*self.op_args, **self.op_kwargs)
  File "/opt/airflow/training/train.py", line 39, in run_models
    mlflow.create_experiment(experiment_name, artifact_uri)
  File "/home/airflow/.local/lib/python3.7/site-packages/mlflow/tracking/fluent.py", line 1082, in create_experiment
    return MlflowClient().create_experiment(name, artifact_location, tags)
  File "/home/airflow/.local/lib/python3.7/site-packages/mlflow/tracking/client.py", line 70, in __init__
    self._tracking_client = TrackingServiceClient(final_tracking_uri)
  File "/home/airflow/.local/lib/python3.7/site-packages/mlflow/tracking/_tracking_service/client.py", line 51, in __init__
    self.store
  File "/home/airflow/.local/lib/python3.7/site-packages/mlflow/tracking/_tracking_service/client.py", line 55, in store
    return utils._get_store(self.tracking_uri)
  File "/home/airflow/.local/lib/python3.7/site-packages/mlflow/tracking/_tracking_service/utils.py", line 186, in _get_store
    return _tracking_store_registry.get_store(store_uri, artifact_uri)
  File "/home/airflow/.local/lib/python3.7/site-packages/mlflow/tracking/_tracking_service/registry.py", line 39, in get_store
    return self._get_store_with_resolved_uri(resolved_store_uri, artifact_uri)
  File "/home/airflow/.local/lib/python3.7/site-packages/mlflow/tracking/_tracking_service/registry.py", line 48, in _get_store_with_resolved_uri
    builder = self.get_store_builder(resolved_store_uri)
  File "/home/airflow/.local/lib/python3.7/site-packages/mlflow/tracking/registry.py", line 73, in get_store_builder
    scheme = store_uri if store_uri == "databricks" else get_uri_scheme(store_uri)
  File "/home/airflow/.local/lib/python3.7/site-packages/mlflow/utils/uri.py", line 166, in get_uri_scheme
    scheme = urllib.parse.urlparse(uri_or_path).scheme
  File "/usr/local/lib/python3.7/urllib/parse.py", line 370, in urlparse
    url, scheme, _coerce_result = _coerce_args(url, scheme)
  File "/usr/local/lib/python3.7/urllib/parse.py", line 126, in _coerce_args
    return _decode_args(args) + (_encode_result,)
  File "/usr/local/lib/python3.7/urllib/parse.py", line 110, in _decode_args
    return tuple(x.decode(encoding, errors) if x else '' for x in args)
  File "/usr/local/lib/python3.7/urllib/parse.py", line 110, in <genexpr>
    return tuple(x.decode(encoding, errors) if x else '' for x in args)
AttributeError: 'tuple' object has no attribute 'decode'
[2022-08-07 18:39:21,254] {taskinstance.py:1420} INFO - Marking task as FAILED. dag_id=training_pipeline_dag, task_id=run_models, execution_date=20220807T183915, start_date=20220807T183921, end_date=20220807T183921
[2022-08-07 18:39:21,266] {standard_task_runner.py:97} ERROR - Failed to execute job 5 for task run_models ('tuple' object has no attribute 'decode'; 160)
[2022-08-07 18:39:21,316] {local_task_job.py:156} INFO - Task exited with return code 1
[2022-08-07 18:39:21,352] {local_task_job.py:273} INFO - 0 downstream tasks scheduled from follow-on schedule check
